<?xml version="1.0"?>
<form>
<bugnb>
15
</bugnb>
<subject>
program fault when for-loop inside a try-block
</subject>
<description>
As soon as a for-loop is contained in the try-block, I get a program fault (segmentation violation). This bug does not occurr when the try-catch construct is contained in the body of a function.
Note: Compiler version is 1.0.3
</description>
<workaround>
dk
</workaround>
<wadescr>

</wadescr>
<priority>
3
</priority>
<bugfile>
/aldor.org/website/bugs/bugreport_15/xxx.as
</bugfile>
<cmdline>
aldor -grun -laldor xxx.as
</cmdline>
<version>
1.0.2
</version>
<email>
Koutschan@risc.uni-linz.ac.at
</email>
<inform>
no
</inform>
<design>
dk
</design>
<typeinf>
dk
</typeinf>
<parsing>
dk
</parsing>
<memory>
dk
</memory>
<optimlvl>
dk
</optimlvl>
<libaldor>
dk
</libaldor>
<algebra>
dk
</algebra>
</form>
